<?xml version="1.0" encoding="utf-8"?>
<!-- This URDF was automatically created by SolidWorks to URDF Exporter! Originally created by Stephen Brawner (brawner@gmail.com)
     Commit Version: 1.6.0-1-g15f4949  Build Version: 1.6.7594.29634
     For more information, please see http://wiki.ros.org/sw_urdf_exporter -->
<robot
  name="bot">
  <link
    name="base_link">
    <inertial>
      <origin
        xyz="0.401088991185585 -0.561832976614903 0.368816143642279"
        rpy="0 0 0" />
      <mass
        value="159.895891670044" />
      <inertia
        ixx="6.50188003696545"
        ixy="0.000775635397345515"
        ixz="0.00298539389816343"
        iyy="8.25828756096125"
        iyz="-0.109631071238321"
        izz="12.4654245059576" />
    </inertial>
    <visual>
      <origin
        xyz="0 0 0"
        rpy="0 0 0" />
      <geometry>
        <mesh
          filename="package://washroom_cleaner/meshes/base_link_bot.STL" />
      </geometry>
      <material
        name="">
        <color
          rgba="0.792156862745098 0.819607843137255 0.933333333333333 1" />
      </material>
    </visual>
    <collision>
      <origin
        xyz="0 0 0"
        rpy="0 0 0" />
      <geometry>
        <mesh
          filename="package://washroom_cleaner/meshes/base_link_bot.STL" />
      </geometry>
    </collision>
  </link>
  <link
    name="link_1">
    <inertial>
      <origin
        xyz="0.0342223057870995 0.141366635926958 0.11265991018794"
        rpy="0 0 0" />
      <mass
        value="10.1002792021682" />
      <inertia
        ixx="0.0987511119270575"
        ixy="0.00480140153344151"
        ixz="0.00307395888740887"
        iyy="0.0774794502237287"
        iyz="-0.00708037336326974"
        izz="0.0715796255243337" />
    </inertial>
    <visual>
      <origin
        xyz="0 0 0"
        rpy="0 0 0" />
      <geometry>
        <mesh
          filename="package://washroom_cleaner/meshes/link_1_bot.STL" />
      </geometry>
      <material
        name="">
        <color
          rgba="0.250980392156863 0.250980392156863 0.250980392156863 1" />
      </material>
    </visual>
    <collision>
      <origin
        xyz="0 0 0"
        rpy="0 0 0" />
      <geometry>
        <mesh
          filename="package://washroom_cleaner/meshes/link_1_bot.STL" />
      </geometry>
    </collision>
  </link>
  <joint
    name="joint_1"
    type="fixed">
    <origin
      xyz="0.27699 -0.62513 0.49989"
      rpy="-1.5708 -0.34065 -1.5708" />
    <parent
      link="base_link" />
    <child
      link="link_1" />
    <axis
      xyz="0 0 0" />
  </joint>
  <link
    name="link_1.2">
    <inertial>
      <origin
        xyz="-0.00569775204612699 -0.000106009865184165 0.020727295078773"
        rpy="0 0 0" />
      <mass
        value="0.18680699175307" />
      <inertia
        ixx="0.000108467851437745"
        ixy="-2.78967323592214E-08"
        ixz="1.08518099809947E-05"
        iyy="0.00011209386427989"
        iyz="1.95890491741231E-08"
        izz="0.000150903701204828" />
    </inertial>
    <visual>
      <origin
        xyz="0 0 0"
        rpy="0 0 0" />
      <geometry>
        <mesh
          filename="package://washroom_cleaner/meshes/link_1.2_bot.STL" />
      </geometry>
      <material
        name="">
        <color
          rgba="0.501960784313725 0.501960784313725 0.501960784313725 1" />
      </material>
    </visual>
    <collision>
      <origin
        xyz="0 0 0"
        rpy="0 0 0" />
      <geometry>
        <mesh
          filename="package://washroom_cleaner/meshes/link_1.2_bot.STL" />
      </geometry>
    </collision>
  </link>
  <joint
    name="joint_1.2"
    type="revolute">
    <origin
      xyz="-0.02917 -0.39539 0.12422"
      rpy="-1.5708 -1.4713 -2.8009" />
    <parent
      link="link_1" />
    <child
      link="link_1.2" />
    <axis
      xyz="0 0 1" />
    <limit
      lower="3.14"
      upper="0"
      effort="0"
      velocity="0" />
  </joint>
  <link
    name="link_1.2.1">
    <inertial>
      <origin
        xyz="0.0580655494615208 0.0013300729572176 0.0142754823090114"
        rpy="0 0 0" />
      <mass
        value="0.083649973397503" />
      <inertia
        ixx="2.13379078089922E-05"
        ixy="1.43500733218594E-06"
        ixz="1.41338643742856E-06"
        iyy="0.000109256671317035"
        iyz="-3.43509398476208E-08"
        izz="0.000107189795764206" />
    </inertial>
    <visual>
      <origin
        xyz="0 0 0"
        rpy="0 0 0" />
      <geometry>
        <mesh
          filename="package://washroom_cleaner/meshes/link_1.2.1_bot.STL" />
      </geometry>
      <material
        name="">
        <color
          rgba="0.792156862745098 0.819607843137255 0.933333333333333 1" />
      </material>
    </visual>
    <collision>
      <origin
        xyz="0 0 0"
        rpy="0 0 0" />
      <geometry>
        <mesh
          filename="package://washroom_cleaner/meshes/link_1.2.1_bot.STL" />
      </geometry>
    </collision>
  </link>
  <joint
    name="joint_1.2.1"
    type="revolute">
    <origin
      xyz="0 0 0.0336947346461056"
      rpy="0 -1.22173047639603 -1.5707963267949" />
    <parent
      link="link_1.2" />
    <child
      link="link_1.2.1" />
    <axis
      xyz="0.939692620785907 0 0.342020143325673" />
    <limit
      lower="3.14"
      upper="0"
      effort="0"
      velocity="0" />
  </joint>
  <link
    name="link_1.2.1-2">
    <inertial>
      <origin
        xyz="-0.129120759127459 -0.000969520216186681 -0.014695438196705"
        rpy="0 0 0" />
      <mass
        value="0.0550083133869526" />
      <inertia
        ixx="8.1609204141315E-06"
        ixy="-2.86720652645581E-19"
        ixz="1.23719749858331E-19"
        iyy="0.000214945524527617"
        iyz="1.18584612615602E-20"
        izz="0.000220874250417479" />
    </inertial>
    <visual>
      <origin
        xyz="0 0 0"
        rpy="0 0 0" />
      <geometry>
        <mesh
          filename="package://washroom_cleaner/meshes/link_1.2.1-2_bot.STL" />
      </geometry>
      <material
        name="">
        <color
          rgba="0.792156862745098 0.819607843137255 0.933333333333333 1" />
      </material>
    </visual>
    <collision>
      <origin
        xyz="0 0 0"
        rpy="0 0 0" />
      <geometry>
        <mesh
          filename="package://washroom_cleaner/meshes/link_1.2.1-2_bot.STL" />
      </geometry>
    </collision>
  </link>
  <joint
    name="joint_1.2.1-2"
    type="revolute">
    <origin
      xyz="0.102177334598959 0 0.0371895084106796"
      rpy="-1.5707963267949 -0.414898179979398 -3.14159265358979" />
    <parent
      link="link_1.2.1" />
    <child
      link="link_1.2.1-2" />
    <axis
      xyz="0.72209941749505 0.691789296862353 0" />
    <limit
      lower="3.14"
      upper="0"
      effort="0"
      velocity="0" />
  </joint>
  <link
    name="Link">
    <inertial>
      <origin
        xyz="0.187048315606571 0.0201228496753146 -0.124647198388031"
        rpy="0 0 0" />
      <mass
        value="0.158326205342065" />
      <inertia
        ixx="3.46195149015416E-05"
        ixy="-1.68893148018066E-07"
        ixz="-2.7533004565103E-07"
        iyy="3.1703173224957E-05"
        iyz="-2.95285123650717E-07"
        izz="3.89884403632016E-05" />
    </inertial>
    <visual>
      <origin
        xyz="0 0 0"
        rpy="0 0 0" />
      <geometry>
        <mesh
          filename="package://washroom_cleaner/meshes/Link_bot.STL" />
      </geometry>
      <material
        name="">
        <color
          rgba="0 0 0 1" />
      </material>
    </visual>
    <collision>
      <origin
        xyz="0 0 0"
        rpy="0 0 0" />
      <geometry>
        <mesh
          filename="package://washroom_cleaner/meshes/Link_bot.STL" />
      </geometry>
    </collision>
  </link>
  <joint
    name="joint"
    type="fixed">
    <origin
      xyz="-0.0952067740222446 -0.0912104700012903 0"
      rpy="-1.5707963267949 0 -3.14159265358979" />
    <parent
      link="link_1.2.1-2" />
    <child
      link="Link" />
    <axis
      xyz="0 0 0" />
  </joint>
  <link
    name="link_2">
    <inertial>
      <origin
        xyz="0.0333060889298056 0.00500000000000006 0.00579000047397271"
        rpy="0 0 0" />
      <mass
        value="0.136953822245057" />
      <inertia
        ixx="3.69621143382842E-05"
        ixy="-1.25214812715429E-21"
        ixz="-4.785757193581E-05"
        iyy="0.000433760500277558"
        iyz="-6.00944577192131E-23"
        izz="0.000399080949643358" />
    </inertial>
    <visual>
      <origin
        xyz="0 0 0"
        rpy="0 0 0" />
      <geometry>
        <mesh
          filename="package://washroom_cleaner/meshes/link_2_bot.STL" />
      </geometry>
      <material
        name="">
        <color
          rgba="0.792156862745098 0.819607843137255 0.933333333333333 1" />
      </material>
    </visual>
    <collision>
      <origin
        xyz="0 0 0"
        rpy="0 0 0" />
      <geometry>
        <mesh
          filename="package://washroom_cleaner/meshes/link_2_bot.STL" />
      </geometry>
    </collision>
  </link>
  <joint
    name="joint_2"
    type="revolute">
    <origin
      xyz="0.363706791161561 -0.963737093432126 0.369809702352455"
      rpy="1.5707963267949 0 0.0721063954480359" />
    <parent
      link="base_link" />
    <child
      link="link_2" />
    <axis
      xyz="0 1 0" />
    <limit
      lower="3.14"
      upper="0"
      effort="0"
      velocity="0" />
  </joint>
  <link
    name="link_2.1">
    <inertial>
      <origin
        xyz="-0.159302367714983 -0.121667828083279 0.191496939311499"
        rpy="0 0 0" />
      <mass
        value="4.885769452176" />
      <inertia
        ixx="0.0182504857476174"
        ixy="-0.00308030713845039"
        ixz="8.43868314392734E-05"
        iyy="0.0164743625405019"
        iyz="4.81030455262835E-05"
        izz="0.0226935778071188" />
    </inertial>
    <visual>
      <origin
        xyz="0 0 0"
        rpy="0 0 0" />
      <geometry>
        <mesh
          filename="package://washroom_cleaner/meshes/link_2.1_bot.STL" />
      </geometry>
      <material
        name="">
        <color
          rgba="1 0.501960784313725 0.501960784313725 1" />
      </material>
    </visual>
    <collision>
      <origin
        xyz="0 0 0"
        rpy="0 0 0" />
      <geometry>
        <mesh
          filename="package://washroom_cleaner/meshes/link_2.1_bot.STL" />
      </geometry>
    </collision>
  </link>
  <joint
    name="joint_2.1"
    type="fixed">
    <origin
      xyz="-0.164114522451131 -0.01 0.137058948749274"
      rpy="0 1.49067939023891 0" />
    <parent
      link="link_2" />
    <child
      link="link_2.1" />
    <axis
      xyz="0 0 0" />
    <limit
      lower="3.14"
      upper="0"
      effort="0"
      velocity="0" />
  </joint>
</robot>
